<?xml version="1.0" encoding="utf-8"?>

<robot
  name="teropobot_full">
  <gazebo>
  <plugin name="gazebo_ros_control" filename="libgazebo_ros_control.so">
    <robotNamespace>/teropobot_full</robotNamespace>
  </plugin>
  </gazebo>

  <link
    name="base_link">
    <inertial>
      <origin
        xyz="0.0416478669573349 -0.00403385726528455 0.0434515211828225"
        rpy="0 0 0" />
      <mass
        value="1.41078792734414" />
      <inertia
        ixx="0.00111400506764418"
        ixy="-4.51157828478083E-10"
        ixz="0.00121758791262258"
        iyy="0.0198527111329821"
        iyz="3.85963214463603E-11"
        izz="0.0190033666741306" />
    </inertial>
    <visual>
      <origin
        xyz="0 0 0"
        rpy="0 0 0" />
      <geometry>
        <mesh
          filename="package://teropobot_full/meshes/base_link.stl" />
      </geometry>
      <material
        name="">
        <color
          rgba="1 1 1 1" />
      </material>
    </visual>
    <collision>
      <origin
        xyz="0 0 0"
        rpy="0 0 0" />
      <geometry>
        <mesh
          filename="package://teropobot_full/meshes/base_link.stl" />
      </geometry>
    </collision>
  </link>
  <link
    name="head_link">
    <inertial>
      <origin
        xyz="-0.021524149927319 -0.0265338780334946 0.0230978429274059"
        rpy="0 0 0" />
      <mass
        value="0.187634452845745" />
      <inertia
        ixx="3.29205933630442E-05"
        ixy="-6.9557189946925E-17"
        ixz="3.53060374200377E-10"
        iyy="0.00107682704483616"
        iyz="-1.07029400464651E-06"
        izz="0.00108318872584713" />
    </inertial>
    <visual>
      <origin
        xyz="0 -0.023 0.00"
        rpy="0 0 0" />
      <geometry>
        <mesh
          filename="package://teropobot_full/meshes/s_0.stl" />
      </geometry>
      <material
        name="">
        <color
          rgba="0.9 1 1 1" />
      </material>
    </visual>
    <collision>
      <origin
        xyz="0 -0.023 0.00"
        rpy="0 0 0" />
      <geometry>
        <mesh
          filename="package://teropobot_full/meshes/s_0.stl" />
      </geometry>
    </collision>
  </link>
  <joint
    name="h_bobbing_joint"
    type="prismatic">
    <origin
      xyz="0.1634 0.0195 0.122"
      rpy="0 0 0" />
    <parent
      link="base_link" />
    <child
      link="head_link" />
    <axis
      xyz="1 0 0" />
    <limit
      lower="-0.06"
      upper="0.02"
      effort="10"
      velocity="10" />
  </joint>
  <link
    name="r_hip_link">
    <inertial>
      <origin
        xyz="-0.0220000063965398 -0.0002848394407447 -0.0489971782635417"
        rpy="0 0 0" />
      <mass
        value="0.247997823174623" />
      <inertia
        ixx="0.000101205620160074"
        ixy="-2.73198286691885E-11"
        ixz="3.85091254605903E-11"
        iyy="8.36561290864557E-05"
        iyz="-2.42574814154466E-06"
        izz="5.209360840728E-05" />
    </inertial>
    <visual>
      <origin
        xyz="-0.079 0.064 -0.1385"
        rpy="0 0 0" />
      <geometry>
        <mesh
          filename="package://teropobot_full/meshes/r_1.stl" />
      </geometry>
      <material
        name="">
        <color
          rgba="0.8 0.8 0.8 1" />
      </material>
    </visual>
    <collision>
      <origin
        xyz="-0.079 0.064 -0.1385"
        rpy="0 0 0" />
      <geometry>
        <mesh
          filename="package://teropobot_full/meshes/r_1.stl" />
      </geometry>
    </collision>
  </link>
  <joint
    name="r_hip_pitch_joint"
    type="revolute">
    <origin
      xyz="0.078905 -0.064 0.13862"
      rpy="0 0 0" />
    <parent
      link="base_link" />
    <child
      link="r_hip_link" />
    <axis
      xyz="1 0 0" />
    <limit
      lower="-0.2"
      upper="0.11"
      effort="100"
      velocity="10" />
  </joint>
  <link
    name="r_femur_link">
    <inertial>
      <origin
        xyz="-1.21365923977379E-08 0.028 -0.0625000000000697"
        rpy="0 0 0" />
      <mass
        value="0.0422410024350713" />
      <inertia
        ixx="7.18043736115381E-05"
        ixy="3.05679866666057E-22"
        ixz="-3.24989272640482E-20"
        iyy="7.45445707922695E-05"
        iyz="1.97499821970278E-20"
        izz="2.76835784902139E-06" />
    </inertial>
    <visual>
      <origin
        xyz="-0.061 0.092 -0.1055"
        rpy="0 0 0" />
      <geometry>
        <mesh
          filename="package://teropobot_full/meshes/r_2.stl" />
      </geometry>
      <material
        name="">
        <color
          rgba="0.2 0.2 0.2 1" />
      </material>
    </visual>
    <collision>
      <origin
        xyz="-0.061 0.092 -0.1055"
        rpy="0 0 0" />
      <geometry>
        <mesh
          filename="package://teropobot_full/meshes/r_2.stl" />
      </geometry>
    </collision>
  </link>
  <joint
    name="r_hip_roll_joint"
    type="revolute">
    <origin
      xyz="-0.018 -0.028 -0.033"
      rpy="0 0 0" />
    <parent
      link="r_hip_link" />
    <child
      link="r_femur_link" />
    <axis
      xyz="0 1 0" />
    <limit
      lower="-1.57"
      upper="1.57"
      effort="100"
      velocity="10" />
  </joint>
  <link
    name="r_tibia_link">
    <inertial>
      <origin
        xyz="-4.76214996325552E-08 0.0276633766737961 -0.0595000000000009"
        rpy="0 0 0" />
      <mass
        value="0.419694987008977" />
      <inertia
        ixx="0.000191800779214511"
        ixy="-8.73001429301117E-20"
        ixz="7.70182498839553E-11"
        iyy="0.000172575599835482"
        iyz="6.5485934829039E-20"
        izz="9.81203758622348E-05" />
    </inertial>
    <visual>
      <origin
        xyz="-0.061 0.092 0.0195"
        rpy="0 0 0" />
      <geometry>
        <mesh
          filename="package://teropobot_full/meshes/r_3.stl" />
      </geometry>
      <material
        name="">
        <color
          rgba="0.6 0.6 0.6 1" />
      </material>
    </visual>
    <collision>
      <origin
        xyz="-0.061 0.092 0.0195"
        rpy="0 0 0" />
      <geometry>
        <mesh
          filename="package://teropobot_full/meshes/r_3.stl" />
      </geometry>
    </collision>
  </link>
  <joint
    name="r_knee_joint"
    type="revolute">
    <origin
      xyz="0 0 -0.125"
      rpy="0 0 0" />
    <parent
      link="r_femur_link" />
    <child
      link="r_tibia_link" />
    <axis
      xyz="0 1 0" />
    <limit
      lower="-0.2"
      upper="1.57"
      effort="100"
      velocity="10" />
  </joint>
  <link
    name="r_metatarsals_link">
    <inertial>
      <origin
        xyz="7.32872484920932E-09 0.0278766423184327 -0.0690622085159465"
        rpy="0 0 0" />
      <mass
        value="0.21645345011941" />
      <inertia
        ixx="8.97348590279341E-05"
        ixy="-2.73182759123709E-11"
        ixz="-3.85091254427449E-11"
        iyy="7.15543482167347E-05"
        iyz="2.42574814154452E-06"
        izz="5.50402868503364E-05" />
    </inertial>
    <visual>
      <origin
        xyz="-0.061 0.092 0.1385"
        rpy="0 0 0" />
      <geometry>
        <mesh
          filename="package://teropobot_full/meshes/r_4.stl" />
      </geometry>
      <material
        name="">
        <color
          rgba="0.898039215686275 0.917647058823529 0.929411764705882 1" />
      </material>
    </visual>
    <collision>
      <origin
        xyz="-0.061 0.092 0.1385"
        rpy="0 0 0" />
      <geometry>
        <mesh
          filename="package://teropobot_full/meshes/r_4.stl" />
      </geometry>
    </collision>
  </link>
  <joint
    name="r_ankle_joint"
    type="revolute">
    <origin
      xyz="0 0 -0.119"
      rpy="0 0 0" />
    <parent
      link="r_tibia_link" />
    <child
      link="r_metatarsals_link" />
    <axis
      xyz="0 1 0" />
    <limit
      lower="-1.57"
      upper="0.64"
      effort="100"
      velocity="10" />
  </joint>
  <link
    name="r_phalanges_link">
    <inertial>
      <origin
        xyz="0.0272000605607781 -0.0101407612836425 0.0367210679469446"
        rpy="0 0 0" />
      <mass
        value="0.0778843023583795" />
      <inertia
        ixx="3.49434622141053E-05"
        ixy="-4.61961003180269E-11"
        ixz="-7.94426883548982E-11"
        iyy="8.92066933457862E-05"
        iyz="7.7658400474191E-07"
        izz="6.0545888001123E-05" />
    </inertial>
    <visual>
      <origin
        xyz="-0.061 0.0925 0.227"
        rpy="0 0 0" />
      <geometry>
        <mesh
          filename="package://teropobot_full/meshes/r_5.stl" />
      </geometry>
      <material
        name="">
        <color
          rgba="0.5 0.5 0.5 1" />
      </material>
    </visual>
    <collision>
      <origin
        xyz="-0.061 0.0925 0.227"
        rpy="0 0 0" />
      <geometry>
        <mesh
          filename="package://teropobot_full/meshes/r_5.stl" />
      </geometry>
    </collision>
  </link>
  <joint
    name="r_phalanges_joint"
    type="revolute">
    <origin
      xyz="0 0 -0.0888"
      rpy="0 0 0" />
    <parent
      link="r_metatarsals_link" />
    <child
      link="r_phalanges_link" />
    <axis
      xyz="0 1 0" />
    <limit
      lower="-0.5"
      upper="1"
      effort="100"
      velocity="10" />
  </joint>

    <link
    name="l_hip_link">
    <inertial>
      <origin
        xyz="-0.0220000063965398 -0.0002848394407447 -0.0489971782635417"
        rpy="0 0 0" />
      <mass
        value="0.247997823174623" />
      <inertia
        ixx="0.000101205620160074"
        ixy="-2.73198286691885E-11"
        ixz="3.85091254605903E-11"
        iyy="8.36561290864557E-05"
        iyz="-2.42574814154466E-06"
        izz="5.209360840728E-05" />
    </inertial>
    <visual>
      <origin
        xyz="-0.079 0.064 -0.1385"
        rpy="0 0 0" />
      <geometry>
        <mesh
          filename="package://teropobot_full/meshes/l_1.stl" />
      </geometry>
      <material
        name="">
        <color
          rgba="0.8 0.8 0.8 1" />
      </material>
    </visual>
    <collision>
      <origin
        xyz="-0.079 0.064 -0.1385"
        rpy="0 0 0" />
      <geometry>
        <mesh
          filename="package://teropobot_full/meshes/l_1.stl" />
      </geometry>
    </collision>
  </link>
  <joint
    name="l_hip_pitch_joint"
    type="revolute">
    <origin
      xyz="0.078905 0.056 0.13862"
      rpy="0 0 0" />
    <parent
      link="base_link" />
    <child
      link="l_hip_link" />
    <axis
      xyz="1 0 0" />
    <limit
      lower="-0.11"
      upper="0.2"
      effort="100"
      velocity="10" />
  </joint>
  <link
    name="l_femur_link">
    <inertial>
      <origin
        xyz="-1.21365923977379E-08 0.028 -0.0625000000000697"
        rpy="0 0 0" />
      <mass
        value="0.0422410024350713" />
      <inertia
        ixx="7.18043736115381E-05"
        ixy="3.05679866666057E-22"
        ixz="-3.24989272640482E-20"
        iyy="7.45445707922695E-05"
        iyz="1.97499821970278E-20"
        izz="2.76835784902139E-06" />
    </inertial>
    <visual>
      <origin
        xyz="-0.061 0.092 -0.1055"
        rpy="0 0 0" />
      <geometry>
        <mesh
          filename="package://teropobot_full/meshes/l_2.stl" />
      </geometry>
      <material
        name="">
        <color
          rgba="0.2 0.2 0.2 1" />
      </material>
    </visual>
    <collision>
      <origin
        xyz="-0.061 0.092 -0.1055"
        rpy="0 0 0" />
      <geometry>
        <mesh
          filename="package://teropobot_full/meshes/l_2.stl" />
      </geometry>
    </collision>
  </link>
  <joint
    name="l_hip_roll_joint"
    type="revolute">
    <origin
      xyz="-0.018 -0.028 -0.033"
      rpy="0 0 0" />
    <parent
      link="l_hip_link" />
    <child
      link="l_femur_link" />
    <axis
      xyz="0 1 0" />
    <limit
      lower="-1.57"
      upper="1.57"
      effort="100"
      velocity="10" />
  </joint>
    <link
    name="l_tibia_link">
    <inertial>
      <origin
        xyz="-4.76214996325552E-08 0.0276633766737961 -0.0595000000000009"
        rpy="0 0 0" />
      <mass
        value="0.419694987008977" />
      <inertia
        ixx="0.000191800779214511"
        ixy="-8.73001429301117E-20"
        ixz="7.70182498839553E-11"
        iyy="0.000172575599835482"
        iyz="6.5485934829039E-20"
        izz="9.81203758622348E-05" />
    </inertial>
    <visual>
      <origin
        xyz="-0.061 0.092 0.0195"
        rpy="0 0 0" />
      <geometry>
        <mesh
          filename="package://teropobot_full/meshes/l_3.stl" />
      </geometry>
      <material
        name="">
        <color
          rgba="0.6 0.6 0.6 1" />
      </material>
    </visual>
    <collision>
      <origin
        xyz="-0.061 0.092 0.0195"
        rpy="0 0 0" />
      <geometry>
        <mesh
          filename="package://teropobot_full/meshes/l_3.stl" />
      </geometry>
    </collision>
  </link>
  <joint
    name="l_knee_joint"
    type="revolute">
    <origin
      xyz="0 0 -0.125"
      rpy="0 0 0" />
    <parent
      link="l_femur_link" />
    <child
      link="l_tibia_link" />
    <axis
      xyz="0 1 0" />
    <limit
      lower="-0.2"
      upper="1.57"
      effort="100"
      velocity="10" />
  </joint>
    <link
    name="l_metatarsals_link">
    <inertial>
      <origin
        xyz="7.32872484920932E-09 0.0278766423184327 -0.0690622085159465"
        rpy="0 0 0" />
      <mass
        value="0.21645345011941" />
      <inertia
        ixx="8.97348590279341E-05"
        ixy="-2.73182759123709E-11"
        ixz="-3.85091254427449E-11"
        iyy="7.15543482167347E-05"
        iyz="2.42574814154452E-06"
        izz="5.50402868503364E-05" />
    </inertial>
    <visual>
      <origin
        xyz="-0.061 0.092 0.1385"
        rpy="0 0 0" />
      <geometry>
        <mesh
          filename="package://teropobot_full/meshes/l_4.stl" />
      </geometry>
      <material
        name="">
        <color
          rgba="0.898039215686275 0.917647058823529 0.929411764705882 1" />
      </material>
    </visual>
    <collision>
      <origin
        xyz="-0.061 0.092 0.1385"
        rpy="0 0 0" />
      <geometry>
        <mesh
          filename="package://teropobot_full/meshes/l_4.stl" />
      </geometry>
    </collision>
  </link>
  <joint
    name="l_ankle_joint"
    type="revolute">
    <origin
      xyz="0 0 -0.119"
      rpy="0 0 0" />
    <parent
      link="l_tibia_link" />
    <child
      link="l_metatarsals_link" />
    <axis
      xyz="0 1 0" />
    <limit
      lower="-1.57"
      upper="0.64"
      effort="100"
      velocity="10" />
  </joint>
  <link
    name="l_phalanges_link">
    <inertial>
      <origin
        xyz="0.0272000605607781 -0.0101407612836425 0.0367210679469446"
        rpy="0 0 0" />
      <mass
        value="0.0778843023583795" />
      <inertia
        ixx="3.49434622141053E-05"
        ixy="-4.61961003180269E-11"
        ixz="-7.94426883548982E-11"
        iyy="8.92066933457862E-05"
        iyz="7.7658400474191E-07"
        izz="6.0545888001123E-05" />
    </inertial>
    <visual>
      <origin
        xyz="-0.061 0.0925 0.227"
        rpy="0 0 0" />
      <geometry>
        <mesh
          filename="package://teropobot_full/meshes/l_5.stl" />
      </geometry>
      <material
        name="">
        <color
          rgba="0.5 0.5 0.5 1" />
      </material>
    </visual>
    <collision>
      <origin
        xyz="-0.061 0.0925 0.227"
        rpy="0 0 0" />
      <geometry>
        <mesh
          filename="package://teropobot_full/meshes/l_5.stl" />
      </geometry>
    </collision>
  </link>
  <joint
    name="l_phalanges_joint"
    type="revolute">
    <origin
      xyz="0 0 -0.0888"
      rpy="0 0 0" />
    <parent
      link="l_metatarsals_link" />
    <child
      link="l_phalanges_link" />
    <axis
      xyz="0 1 0" />
    <limit
      lower="-0.5"
      upper="1"
      effort="100"
      velocity="10" />
  </joint>

  <!-- Transmissions -->
  <transmission name="l_hip_pitch_joint_transmission">
    <type>transmission_interface/SimpleTransmission</type>
    <joint name="l_pelvis_joint">
      <hardwareInterface>EffortJointInterface</hardwareInterface>
    </joint> 
    <actuator name="l_hip_pitch_joint_motor">
      <hardwareInterface>EffortJointInterface</hardwareInterface>
      <mechanicalReduction>1</mechanicalReduction>
    </actuator>
  </transmission>










</robot>